````javascript
//既然有错误类型，那么就肯定可以捕获错误信息
//手动抛出错误的方法：try catch finally throw
console.log('正常执行1')
console.log(b)
console.log('正常执行2')
//执行到第二个日志的时候浏览器会抛出一个引用错误，下面的代码就不再执行了。
//使用try catch手动的捕获错误和抛出错误
var str = ''
try{
    if(!str){
        //手动的抛出自定义错误信息
        throw '自定义错误';
    }
    console.log('正常执行1')
	console.log(b)
	console.log('正常执行2')
}catch(err){
    //在try中捕获到错误的代码就会进入到catch中
    //因为Error构造函数对象是所有错误类型的父类，所有可以使用Error原型上的name和message属性
    console.log(err.name+':'+err.message)
    console.log(err)
}finally{
    //不管try和catch的执行结果如何都会进入到finally里面来
    console.log('正常执行3')
}
//在try catch外面写的代码也是一样可以正常运行的
console.log('正常执行4')
````

